<?xml version="1.0" ?>
<!-- =================================================================================== -->
<!-- |    This document was autogenerated by xacro from model.xarco                    | -->
<!-- |    EDITING THIS FILE BY HAND IS NOT RECOMMENDED                                 | -->
<!-- =================================================================================== -->
<robot name="robot_name">
  <link name="base_link"/>
  <joint name="base_joint" type="fixed">
    <parent link="base_link"/>
    <child link="body"/>
    <origin rpy="3.141592653589793 0 0" xyz="0 0 0"/>
  </joint>
  <link name="body">
    <visual>
      <origin rpy="0 0 0" xyz="0 0 0"/>
      <geometry>
        <mesh filename="package://hexapod_description/meshes/thorax.STL" scale="1.0 1.0 1.0"/>
      </geometry>
      <material name="grey">
        <color rgba="0.5 0.5 0.5 1"/>
      </material>
    </visual>
    <inertial>
      <origin rpy="0 0 0" xyz="0.000000 0.000000 0.000000"/>
      <mass value="0.01"/>
      <inertia ixx="0.01" ixy="0" ixz="0" iyy="0.01" iyz="0" izz="0.01"/>
    </inertial>
  </link>
  <joint name="leg_joint_r1" type="fixed">
    <parent link="body"/>
    <child link="leg_centre_r1"/>
    <origin rpy="0.0 0.0 0.0" xyz="0.087598 -0.050575 0.0"/>
  </joint>
  <link name="leg_centre_r1">
    <inertial>
      <origin rpy="0.0 0.0 0.0" xyz="0.0 0.0 0.0"/>
      <mass value="0.01"/>
      <inertia ixx="0.01" ixy="0.0" ixz="0.0" iyy="0.01" iyz="0.0" izz="0.01"/>
    </inertial>
  </link>
  <joint name="coxa_joint_r1" type="revolute">
    <parent link="leg_centre_r1"/>
    <child link="coxa_r1"/>
    <axis xyz="0 0 -1"/>
    <limit effort="1000.0" lower="-1.5" upper="1.5" velocity="100.0"/>
    <origin rpy="0 0 -1.0471975511965976" xyz="0 0 0"/>
  </joint>
  <link name="coxa_r1">
    <inertial>
      <origin rpy="0.0 0.0 0.0" xyz="0.0 0.0 0.0"/>
      <mass value="0.01"/>
      <inertia ixx="0.01" ixy="0.0" ixz="0.0" iyy="0.01" iyz="0.0" izz="0.01"/>
    </inertial>
    <visual>
      <origin rpy="0.0 0.0 0.0" xyz="0.0 0.0 0.0"/>
      <geometry>
        <mesh filename="package://hexapod_description/meshes/coxa_r.STL" scale="1.0 1.0 1.0"/>
      </geometry>
      <material name="">
        <color rgba="0.7 0.0 0.1"/>
      </material>
    </visual>
  </link>
  <joint name="femur_joint_r1" type="revolute">
    <parent link="coxa_r1"/>
    <child link="femur_r1"/>
    <axis xyz="0 0 -1"/>
    <limit effort="1000.0" lower="-1.5" upper="1.5" velocity="100.0"/>
    <origin rpy="-1.57 0 0" xyz="0.0294 0 0"/>
  </joint>
  <link name="femur_r1">
    <inertial>
      <origin rpy="0.0 0.0 0.0" xyz="0.0 0.0 0.0"/>
      <mass value="0.001"/>
      <inertia ixx="0.001" ixy="0.0" ixz="0.0" iyy="0.001" iyz="0.0" izz="0.001"/>
    </inertial>
    <visual name="">
      <origin rpy="0.0 0.0 0.0" xyz="0.0 0.0 0.0"/>
      <geometry>
        <mesh filename="package://hexapod_description/meshes/femur_r.STL"/>
      </geometry>
      <material name="">
        <color rgba="0 0.7 0.7 1.0"/>
      </material>
    </visual>
  </link>
  <joint name="tibia_joint_r1" type="revolute">
    <origin rpy="0.0 0.0 0.0" xyz="0.08 0.0 0.0"/>
    <parent link="femur_r1"/>
    <child link="tibia_r1"/>
    <axis xyz="0 0 1"/>
    <limit effort="1000.0" lower="-1.5" upper="1.5" velocity="100.0"/>
  </joint>
  <link name="tibia_r1">
    <inertial>
      <origin rpy="0.0 0.0 0.0" xyz="0.117 0.0 0.0"/>
      <mass value="0.01"/>
      <inertia ixx="0.01" ixy="0.0" ixz="0.0" iyy="0.01" iyz="0.0" izz="0.01"/>
    </inertial>
    <visual name="">
      <origin rpy="0.0 0.0 0.06" xyz="0.0 0.0 0.0"/>
      <geometry>
        <mesh filename="package://hexapod_description/meshes/tibia_r.STL" scale="1.0 1.0 1.0"/>
      </geometry>
      <material name="">
        <color rgba="0 0.7 0.7 1.0"/>
      </material>
    </visual>
  </link>
  <joint name="tibia_foot_joint_r1" type="fixed">
    <origin rpy="0 0 0" xyz="0.117 0 0"/>
    <parent link="tibia_r1"/>
    <child link="tibia_foot_r1"/>
  </joint>
  <link name="tibia_foot_r1">
    <inertial>
      <origin rpy="0 0 0" xyz="0.000000 0.000000 0.000000"/>
      <mass value="0.01"/>
      <inertia ixx="0.01" ixy="0" ixz="0" iyy="0.01" iyz="0" izz="0.01"/>
    </inertial>
  </link>
  <joint name="leg_joint_r2" type="fixed">
    <parent link="body"/>
    <child link="leg_centre_r2"/>
    <origin rpy="0.0 0.0 0.0" xyz="0 -0.06985 0.0"/>
  </joint>
  <link name="leg_centre_r2">
    <inertial>
      <origin rpy="0.0 0.0 0.0" xyz="0.0 0.0 0.0"/>
      <mass value="0.01"/>
      <inertia ixx="0.01" ixy="0.0" ixz="0.0" iyy="0.01" iyz="0.0" izz="0.01"/>
    </inertial>
  </link>
  <joint name="coxa_joint_r2" type="revolute">
    <parent link="leg_centre_r2"/>
    <child link="coxa_r2"/>
    <axis xyz="0 0 -1"/>
    <limit effort="1000.0" lower="-1.5" upper="1.5" velocity="100.0"/>
    <origin rpy="0 0 -1.5707963267948966" xyz="0 0 0"/>
  </joint>
  <link name="coxa_r2">
    <inertial>
      <origin rpy="0.0 0.0 0.0" xyz="0.0 0.0 0.0"/>
      <mass value="0.01"/>
      <inertia ixx="0.01" ixy="0.0" ixz="0.0" iyy="0.01" iyz="0.0" izz="0.01"/>
    </inertial>
    <visual>
      <origin rpy="0.0 0.0 0.0" xyz="0.0 0.0 0.0"/>
      <geometry>
        <mesh filename="package://hexapod_description/meshes/coxa_r.STL" scale="1.0 1.0 1.0"/>
      </geometry>
      <material name="">
        <color rgba="0.7 0.0 0.1"/>
      </material>
    </visual>
  </link>
  <joint name="femur_joint_r2" type="revolute">
    <parent link="coxa_r2"/>
    <child link="femur_r2"/>
    <axis xyz="0 0 -1"/>
    <limit effort="1000.0" lower="-1.5" upper="1.5" velocity="100.0"/>
    <origin rpy="-1.57 0 0" xyz="0.0294 0 0"/>
  </joint>
  <link name="femur_r2">
    <inertial>
      <origin rpy="0.0 0.0 0.0" xyz="0.0 0.0 0.0"/>
      <mass value="0.001"/>
      <inertia ixx="0.001" ixy="0.0" ixz="0.0" iyy="0.001" iyz="0.0" izz="0.001"/>
    </inertial>
    <visual name="">
      <origin rpy="0.0 0.0 0.0" xyz="0.0 0.0 0.0"/>
      <geometry>
        <mesh filename="package://hexapod_description/meshes/femur_r.STL"/>
      </geometry>
      <material name="">
        <color rgba="0 0.7 0.7 1.0"/>
      </material>
    </visual>
  </link>
  <joint name="tibia_joint_r2" type="revolute">
    <origin rpy="0.0 0.0 0.0" xyz="0.08 0.0 0.0"/>
    <parent link="femur_r2"/>
    <child link="tibia_r2"/>
    <axis xyz="0 0 1"/>
    <limit effort="1000.0" lower="-1.5" upper="1.5" velocity="100.0"/>
  </joint>
  <link name="tibia_r2">
    <inertial>
      <origin rpy="0.0 0.0 0.0" xyz="0.117 0.0 0.0"/>
      <mass value="0.01"/>
      <inertia ixx="0.01" ixy="0.0" ixz="0.0" iyy="0.01" iyz="0.0" izz="0.01"/>
    </inertial>
    <visual name="">
      <origin rpy="0.0 0.0 0.06" xyz="0.0 0.0 0.0"/>
      <geometry>
        <mesh filename="package://hexapod_description/meshes/tibia_r.STL" scale="1.0 1.0 1.0"/>
      </geometry>
      <material name="">
        <color rgba="0 0.7 0.7 1.0"/>
      </material>
    </visual>
  </link>
  <joint name="tibia_foot_joint_r2" type="fixed">
    <origin rpy="0 0 0" xyz="0.117 0 0"/>
    <parent link="tibia_r2"/>
    <child link="tibia_foot_r2"/>
  </joint>
  <link name="tibia_foot_r2">
    <inertial>
      <origin rpy="0 0 0" xyz="0.000000 0.000000 0.000000"/>
      <mass value="0.01"/>
      <inertia ixx="0.01" ixy="0" ixz="0" iyy="0.01" iyz="0" izz="0.01"/>
    </inertial>
  </link>
  <joint name="leg_joint_r3" type="fixed">
    <parent link="body"/>
    <child link="leg_centre_r3"/>
    <origin rpy="0.0 0.0 0.0" xyz="-0.087598 -0.050575 0.0"/>
  </joint>
  <link name="leg_centre_r3">
    <inertial>
      <origin rpy="0.0 0.0 0.0" xyz="0.0 0.0 0.0"/>
      <mass value="0.01"/>
      <inertia ixx="0.01" ixy="0.0" ixz="0.0" iyy="0.01" iyz="0.0" izz="0.01"/>
    </inertial>
  </link>
  <joint name="coxa_joint_r3" type="revolute">
    <parent link="leg_centre_r3"/>
    <child link="coxa_r3"/>
    <axis xyz="0 0 -1"/>
    <limit effort="1000.0" lower="-1.5" upper="1.5" velocity="100.0"/>
    <origin rpy="0 0 -2.0943951023931953" xyz="0 0 0"/>
  </joint>
  <link name="coxa_r3">
    <inertial>
      <origin rpy="0.0 0.0 0.0" xyz="0.0 0.0 0.0"/>
      <mass value="0.01"/>
      <inertia ixx="0.01" ixy="0.0" ixz="0.0" iyy="0.01" iyz="0.0" izz="0.01"/>
    </inertial>
    <visual>
      <origin rpy="0.0 0.0 0.0" xyz="0.0 0.0 0.0"/>
      <geometry>
        <mesh filename="package://hexapod_description/meshes/coxa_r.STL" scale="1.0 1.0 1.0"/>
      </geometry>
      <material name="">
        <color rgba="0.7 0.0 0.1"/>
      </material>
    </visual>
  </link>
  <joint name="femur_joint_r3" type="revolute">
    <parent link="coxa_r3"/>
    <child link="femur_r3"/>
    <axis xyz="0 0 -1"/>
    <limit effort="1000.0" lower="-1.5" upper="1.5" velocity="100.0"/>
    <origin rpy="-1.57 0 0" xyz="0.0294 0 0"/>
  </joint>
  <link name="femur_r3">
    <inertial>
      <origin rpy="0.0 0.0 0.0" xyz="0.0 0.0 0.0"/>
      <mass value="0.001"/>
      <inertia ixx="0.001" ixy="0.0" ixz="0.0" iyy="0.001" iyz="0.0" izz="0.001"/>
    </inertial>
    <visual name="">
      <origin rpy="0.0 0.0 0.0" xyz="0.0 0.0 0.0"/>
      <geometry>
        <mesh filename="package://hexapod_description/meshes/femur_r.STL"/>
      </geometry>
      <material name="">
        <color rgba="0 0.7 0.7 1.0"/>
      </material>
    </visual>
  </link>
  <joint name="tibia_joint_r3" type="revolute">
    <origin rpy="0.0 0.0 0.0" xyz="0.08 0.0 0.0"/>
    <parent link="femur_r3"/>
    <child link="tibia_r3"/>
    <axis xyz="0 0 1"/>
    <limit effort="1000.0" lower="-1.5" upper="1.5" velocity="100.0"/>
  </joint>
  <link name="tibia_r3">
    <inertial>
      <origin rpy="0.0 0.0 0.0" xyz="0.117 0.0 0.0"/>
      <mass value="0.01"/>
      <inertia ixx="0.01" ixy="0.0" ixz="0.0" iyy="0.01" iyz="0.0" izz="0.01"/>
    </inertial>
    <visual name="">
      <origin rpy="0.0 0.0 0.06" xyz="0.0 0.0 0.0"/>
      <geometry>
        <mesh filename="package://hexapod_description/meshes/tibia_r.STL" scale="1.0 1.0 1.0"/>
      </geometry>
      <material name="">
        <color rgba="0 0.7 0.7 1.0"/>
      </material>
    </visual>
  </link>
  <joint name="tibia_foot_joint_r3" type="fixed">
    <origin rpy="0 0 0" xyz="0.117 0 0"/>
    <parent link="tibia_r3"/>
    <child link="tibia_foot_r3"/>
  </joint>
  <link name="tibia_foot_r3">
    <inertial>
      <origin rpy="0 0 0" xyz="0.000000 0.000000 0.000000"/>
      <mass value="0.01"/>
      <inertia ixx="0.01" ixy="0" ixz="0" iyy="0.01" iyz="0" izz="0.01"/>
    </inertial>
  </link>
  <joint name="leg_joint_l1" type="fixed">
    <parent link="body"/>
    <child link="leg_centre_l1"/>
    <origin rpy="0.0 0.0 0.0" xyz="0.087598 0.050575 0.0"/>
  </joint>
  <link name="leg_centre_l1">
    <inertial>
      <origin rpy="0.0 0.0 0.0" xyz="0.0 0.0 0.0"/>
      <mass value="0.01"/>
      <inertia ixx="0.01" ixy="0.0" ixz="0.0" iyy="0.01" iyz="0.0" izz="0.01"/>
    </inertial>
  </link>
  <joint name="coxa_joint_l1" type="revolute">
    <parent link="leg_centre_l1"/>
    <child link="coxa_l1"/>
    <axis xyz="0 0 -1"/>
    <limit effort="1000.0" lower="-1.5" upper="1.5" velocity="100.0"/>
    <origin rpy="0 0 1.0471975511965976" xyz="0 0 0"/>
  </joint>
  <link name="coxa_l1">
    <inertial>
      <origin rpy="0.0 0.0 0.0" xyz="0.0 0.0 0.0"/>
      <mass value="0.01"/>
      <inertia ixx="0.01" ixy="0.0" ixz="0.0" iyy="0.01" iyz="0.0" izz="0.01"/>
    </inertial>
    <visual>
      <origin rpy="0.0 0.0 0.0" xyz="0.0 0.0 0.0"/>
      <geometry>
        <mesh filename="package://hexapod_description/meshes/coxa_l.STL" scale="1.0 1.0 1.0"/>
      </geometry>
      <material name="">
        <color rgba="0.7 0.0 0.1"/>
      </material>
    </visual>
  </link>
  <joint name="femur_joint_l1" type="revolute">
    <parent link="coxa_l1"/>
    <child link="femur_l1"/>
    <axis xyz="0 0 -1"/>
    <limit effort="1000.0" lower="-1.5" upper="1.5" velocity="100.0"/>
    <origin rpy="-1.57 0 0" xyz="0.0294 0 0"/>
  </joint>
  <link name="femur_l1">
    <inertial>
      <origin rpy="0.0 0.0 0.0" xyz="0.0 0.0 0.0"/>
      <mass value="0.001"/>
      <inertia ixx="0.001" ixy="0.0" ixz="0.0" iyy="0.001" iyz="0.0" izz="0.001"/>
    </inertial>
    <visual name="">
      <origin rpy="0.0 0.0 0.0" xyz="0.0 0.0 0.0"/>
      <geometry>
        <mesh filename="package://hexapod_description/meshes/femur_l.STL"/>
      </geometry>
      <material name="">
        <color rgba="0 0.7 0.7 1.0"/>
      </material>
    </visual>
  </link>
  <joint name="tibia_joint_l1" type="revolute">
    <origin rpy="0.0 0.0 0.0" xyz="0.08 0.0 0.0"/>
    <parent link="femur_l1"/>
    <child link="tibia_l1"/>
    <axis xyz="0 0 1"/>
    <limit effort="1000.0" lower="-1.5" upper="1.5" velocity="100.0"/>
  </joint>
  <link name="tibia_l1">
    <inertial>
      <origin rpy="0.0 0.0 0.0" xyz="0.117 0.0 0.0"/>
      <mass value="0.01"/>
      <inertia ixx="0.01" ixy="0.0" ixz="0.0" iyy="0.01" iyz="0.0" izz="0.01"/>
    </inertial>
    <visual name="">
      <origin rpy="0.0 0.0 0.06" xyz="0.0 0.0 0.0"/>
      <geometry>
        <mesh filename="package://hexapod_description/meshes/tibia_l.STL" scale="1.0 1.0 1.0"/>
      </geometry>
      <material name="">
        <color rgba="0 0.7 0.7 1.0"/>
      </material>
    </visual>
  </link>
  <joint name="tibia_foot_joint_l1" type="fixed">
    <origin rpy="0 0 0" xyz="0.117 0 0"/>
    <parent link="tibia_l1"/>
    <child link="tibia_foot_l1"/>
  </joint>
  <link name="tibia_foot_l1">
    <inertial>
      <origin rpy="0 0 0" xyz="0.000000 0.000000 0.000000"/>
      <mass value="0.01"/>
      <inertia ixx="0.01" ixy="0" ixz="0" iyy="0.01" iyz="0" izz="0.01"/>
    </inertial>
  </link>
  <joint name="leg_joint_l2" type="fixed">
    <parent link="body"/>
    <child link="leg_centre_l2"/>
    <origin rpy="0.0 0.0 0.0" xyz="0 0.06985 0.0"/>
  </joint>
  <link name="leg_centre_l2">
    <inertial>
      <origin rpy="0.0 0.0 0.0" xyz="0.0 0.0 0.0"/>
      <mass value="0.01"/>
      <inertia ixx="0.01" ixy="0.0" ixz="0.0" iyy="0.01" iyz="0.0" izz="0.01"/>
    </inertial>
  </link>
  <joint name="coxa_joint_l2" type="revolute">
    <parent link="leg_centre_l2"/>
    <child link="coxa_l2"/>
    <axis xyz="0 0 -1"/>
    <limit effort="1000.0" lower="-1.5" upper="1.5" velocity="100.0"/>
    <origin rpy="0 0 1.5707963267948966" xyz="0 0 0"/>
  </joint>
  <link name="coxa_l2">
    <inertial>
      <origin rpy="0.0 0.0 0.0" xyz="0.0 0.0 0.0"/>
      <mass value="0.01"/>
      <inertia ixx="0.01" ixy="0.0" ixz="0.0" iyy="0.01" iyz="0.0" izz="0.01"/>
    </inertial>
    <visual>
      <origin rpy="0.0 0.0 0.0" xyz="0.0 0.0 0.0"/>
      <geometry>
        <mesh filename="package://hexapod_description/meshes/coxa_l.STL" scale="1.0 1.0 1.0"/>
      </geometry>
      <material name="">
        <color rgba="0.7 0.0 0.1"/>
      </material>
    </visual>
  </link>
  <joint name="femur_joint_l2" type="revolute">
    <parent link="coxa_l2"/>
    <child link="femur_l2"/>
    <axis xyz="0 0 -1"/>
    <limit effort="1000.0" lower="-1.5" upper="1.5" velocity="100.0"/>
    <origin rpy="-1.57 0 0" xyz="0.0294 0 0"/>
  </joint>
  <link name="femur_l2">
    <inertial>
      <origin rpy="0.0 0.0 0.0" xyz="0.0 0.0 0.0"/>
      <mass value="0.001"/>
      <inertia ixx="0.001" ixy="0.0" ixz="0.0" iyy="0.001" iyz="0.0" izz="0.001"/>
    </inertial>
    <visual name="">
      <origin rpy="0.0 0.0 0.0" xyz="0.0 0.0 0.0"/>
      <geometry>
        <mesh filename="package://hexapod_description/meshes/femur_l.STL"/>
      </geometry>
      <material name="">
        <color rgba="0 0.7 0.7 1.0"/>
      </material>
    </visual>
  </link>
  <joint name="tibia_joint_l2" type="revolute">
    <origin rpy="0.0 0.0 0.0" xyz="0.08 0.0 0.0"/>
    <parent link="femur_l2"/>
    <child link="tibia_l2"/>
    <axis xyz="0 0 1"/>
    <limit effort="1000.0" lower="-1.5" upper="1.5" velocity="100.0"/>
  </joint>
  <link name="tibia_l2">
    <inertial>
      <origin rpy="0.0 0.0 0.0" xyz="0.117 0.0 0.0"/>
      <mass value="0.01"/>
      <inertia ixx="0.01" ixy="0.0" ixz="0.0" iyy="0.01" iyz="0.0" izz="0.01"/>
    </inertial>
    <visual name="">
      <origin rpy="0.0 0.0 0.06" xyz="0.0 0.0 0.0"/>
      <geometry>
        <mesh filename="package://hexapod_description/meshes/tibia_l.STL" scale="1.0 1.0 1.0"/>
      </geometry>
      <material name="">
        <color rgba="0 0.7 0.7 1.0"/>
      </material>
    </visual>
  </link>
  <joint name="tibia_foot_joint_l2" type="fixed">
    <origin rpy="0 0 0" xyz="0.117 0 0"/>
    <parent link="tibia_l2"/>
    <child link="tibia_foot_l2"/>
  </joint>
  <link name="tibia_foot_l2">
    <inertial>
      <origin rpy="0 0 0" xyz="0.000000 0.000000 0.000000"/>
      <mass value="0.01"/>
      <inertia ixx="0.01" ixy="0" ixz="0" iyy="0.01" iyz="0" izz="0.01"/>
    </inertial>
  </link>
  <joint name="leg_joint_l3" type="fixed">
    <parent link="body"/>
    <child link="leg_centre_l3"/>
    <origin rpy="0.0 0.0 0.0" xyz="-0.087598 0.050575 0.0"/>
  </joint>
  <link name="leg_centre_l3">
    <inertial>
      <origin rpy="0.0 0.0 0.0" xyz="0.0 0.0 0.0"/>
      <mass value="0.01"/>
      <inertia ixx="0.01" ixy="0.0" ixz="0.0" iyy="0.01" iyz="0.0" izz="0.01"/>
    </inertial>
  </link>
  <joint name="coxa_joint_l3" type="revolute">
    <parent link="leg_centre_l3"/>
    <child link="coxa_l3"/>
    <axis xyz="0 0 -1"/>
    <limit effort="1000.0" lower="-1.5" upper="1.5" velocity="100.0"/>
    <origin rpy="0 0 2.0943951023931953" xyz="0 0 0"/>
  </joint>
  <link name="coxa_l3">
    <inertial>
      <origin rpy="0.0 0.0 0.0" xyz="0.0 0.0 0.0"/>
      <mass value="0.01"/>
      <inertia ixx="0.01" ixy="0.0" ixz="0.0" iyy="0.01" iyz="0.0" izz="0.01"/>
    </inertial>
    <visual>
      <origin rpy="0.0 0.0 0.0" xyz="0.0 0.0 0.0"/>
      <geometry>
        <mesh filename="package://hexapod_description/meshes/coxa_l.STL" scale="1.0 1.0 1.0"/>
      </geometry>
      <material name="">
        <color rgba="0.7 0.0 0.1"/>
      </material>
    </visual>
  </link>
  <joint name="femur_joint_l3" type="revolute">
    <parent link="coxa_l3"/>
    <child link="femur_l3"/>
    <axis xyz="0 0 -1"/>
    <limit effort="1000.0" lower="-1.5" upper="1.5" velocity="100.0"/>
    <origin rpy="-1.57 0 0" xyz="0.0294 0 0"/>
  </joint>
  <link name="femur_l3">
    <inertial>
      <origin rpy="0.0 0.0 0.0" xyz="0.0 0.0 0.0"/>
      <mass value="0.001"/>
      <inertia ixx="0.001" ixy="0.0" ixz="0.0" iyy="0.001" iyz="0.0" izz="0.001"/>
    </inertial>
    <visual name="">
      <origin rpy="0.0 0.0 0.0" xyz="0.0 0.0 0.0"/>
      <geometry>
        <mesh filename="package://hexapod_description/meshes/femur_l.STL"/>
      </geometry>
      <material name="">
        <color rgba="0 0.7 0.7 1.0"/>
      </material>
    </visual>
  </link>
  <joint name="tibia_joint_l3" type="revolute">
    <origin rpy="0.0 0.0 0.0" xyz="0.08 0.0 0.0"/>
    <parent link="femur_l3"/>
    <child link="tibia_l3"/>
    <axis xyz="0 0 1"/>
    <limit effort="1000.0" lower="-1.5" upper="1.5" velocity="100.0"/>
  </joint>
  <link name="tibia_l3">
    <inertial>
      <origin rpy="0.0 0.0 0.0" xyz="0.117 0.0 0.0"/>
      <mass value="0.01"/>
      <inertia ixx="0.01" ixy="0.0" ixz="0.0" iyy="0.01" iyz="0.0" izz="0.01"/>
    </inertial>
    <visual name="">
      <origin rpy="0.0 0.0 0.06" xyz="0.0 0.0 0.0"/>
      <geometry>
        <mesh filename="package://hexapod_description/meshes/tibia_l.STL" scale="1.0 1.0 1.0"/>
      </geometry>
      <material name="">
        <color rgba="0 0.7 0.7 1.0"/>
      </material>
    </visual>
  </link>
  <joint name="tibia_foot_joint_l3" type="fixed">
    <origin rpy="0 0 0" xyz="0.117 0 0"/>
    <parent link="tibia_l3"/>
    <child link="tibia_foot_l3"/>
  </joint>
  <link name="tibia_foot_l3">
    <inertial>
      <origin rpy="0 0 0" xyz="0.000000 0.000000 0.000000"/>
      <mass value="0.01"/>
      <inertia ixx="0.01" ixy="0" ixz="0" iyy="0.01" iyz="0" izz="0.01"/>
    </inertial>
  </link>
</robot>
