<?xml version="1.0"?>
<robot xmlns:xacro="http://www.ros.org/wiki/xacro">

    <xacro:property name="friction" value="0.4"/>
    <xacro:property name="joint_vel" value="2.0"/>
    <xacro:property name="joint_effort" value="100.0"/>
    
    <link name="base_link"/>

    <joint name="base_joint" type="fixed">
        <parent link="base_link"/>
        <child link="body"/>
        <origin xyz="0 0 0.45" rpy="${pi} 0 0"/>
    </joint>

    <link name="body">
        <visual>
            <origin xyz="0 0 0" rpy="0 0 0"/>
            <geometry>
                <mesh filename="file://$(find hexapod_description)/meshes/thorax.STL" scale="3.0 3.0 3.0"/>
            </geometry>
            <material name="black"/>
        </visual>

        <collision>
            <origin xyz="0 0 0" rpy="0 0 0"/>
            <geometry>
                <box size="0.5 0.32 0.15"/>
            </geometry>
        </collision>

        <xacro:box_inertia m="0.3" x="0.5" y="0.32" z="0.15" o_xyz="0 0 0" o_rpy="0 0 0"/>
    </link>

    <xacro:macro name="leg" params="side num coxa_y_val femur_z_val tibia_box_z_val x y ang">

        <joint name="leg_joint_${side}${num}" type="fixed">
            <parent link="body"/>
            <child link="leg_centre_${side}${num}"/>
            <origin xyz="${x} ${y} 0.0" rpy="0.0 0.0 0.0"/>
        </joint>

        <link name="leg_centre_${side}${num}"/>

        <joint name="coxa_joint_${side}${num}" type="revolute">
            <parent link="leg_centre_${side}${num}"/>
            <child link="coxa_${side}${num}"/>
            <axis xyz="0 0 -1"/>
            <limit lower="-1.04" upper="1.04" velocity="${joint_vel}" effort="${joint_effort}"/>
            <dynamics damping="0.0" friction="${friction}"/>
            <origin xyz="0 0 0" rpy="0 0 ${ang}"/>
        </joint>

        <link name="coxa_${side}${num}">
            <visual>
                <origin xyz="0.0 0.0 0.0" rpy="0.0 0.0 0.0"/>
                <geometry>
                    <mesh filename="file://$(find hexapod_description)/meshes/coxa_${side}.STL" scale="3.0 3.0 3.0"/>
                </geometry>
                <material name="teal" />
            </visual>

            <collision>
                <origin xyz="0.05 ${coxa_y_val} 0.02" rpy="0.0 0.0 0.0"/>
                <geometry>
                    <box size="0.16 0.17 0.16"/>
                </geometry>
            </collision>

            <xacro:box_inertia m="0.015" x="0.16" y="0.17" z="0.16" o_xyz="0 0 0" o_rpy="0 0 0"/>
        </link>

        <joint name="femur_joint_${side}${num}" type="revolute">
            <parent link="coxa_${side}${num}"/>
            <child link="femur_${side}${num}"/>
            <axis xyz="0 0 -1"/>
            <limit lower="-1.04" upper="1.04" velocity="${joint_vel}" effort="${joint_effort}"/>
            <dynamics damping="0.0" friction="${friction}"/>
            <origin xyz="0.0882 0 0" rpy="-1.57 0 0"/>
        </joint>
        
        <link name="femur_${side}${num}">
            <visual>
                <origin xyz="0.0 0.0 0.0" rpy="0.0 0.0 0.0"/>
                <geometry>
                    <mesh filename="file://$(find hexapod_description)/meshes/femur_${side}.STL" scale="3.0 3.0 3.0"/>
                </geometry>
                <material name="teal" />
            </visual>

            <collision>
                <origin xyz="0.12 0.0 ${femur_z_val}" rpy="0.0 0.0 0.0"/>
                <geometry>
                    <box size="0.3 0.06 0.006"/>
                </geometry>
            </collision>

            <xacro:box_inertia m="0.012" x="0.3" y="0.06" z="0.006" o_xyz="0.12 0.0 ${femur_z_val}" o_rpy="0 0 0"/>
        </link>

        <joint name="tibia_joint_${side}${num}" type="revolute">
            <origin xyz="0.24 0.0 0.0" rpy="0.0 0.0 -1.1"/>
            <parent link="femur_${side}${num}"/>
            <child link="tibia_${side}${num}"/>
            <axis xyz="0 0 1"/>
            <limit lower="-0.7" upper="1.57" velocity="${joint_vel}" effort="${joint_effort}"/>
            <dynamics damping="0.0" friction="${friction}"/>
        </joint>

        <link name="tibia_${side}${num}">
            <visual name="">
                <origin xyz="0.0 0.0 0.0" rpy="0.0 0.0 0.06"/>
                <geometry>
                    <mesh filename="file://$(find hexapod_description)/meshes/tibia_${side}.STL" scale="3.0 3.0 3.0"/>
                </geometry>
                <material name="teal" />
            </visual>

            <collision>
                <origin xyz="-0.035 0.0 ${tibia_box_z_val}" rpy="0.0 0.0 0.06"/>
                <geometry>
                    <box size="0.13 0.05 0.12"/>
                </geometry>
            </collision>
            <collision>
                <origin xyz="0.085 0 0" rpy="0.0 0.0 0.06"/>
                <geometry>
                    <box size="0.48 0.02 0.006"/>
                </geometry>
            </collision>

            <xacro:box_inertia m="0.015" x="0.3" y="0.05" z="0.05" o_xyz="-0.035 0.0 ${tibia_box_z_val}" o_rpy="0 0 0"/>
        </link>


        
    </xacro:macro>

    <xacro:leg side="r" num="1" coxa_y_val = "-0.03" femur_z_val = "0.067" tibia_box_z_val = "0.008" x="0.262794" 	y="-0.151725" 	ang="-${pi/3}" />
	<xacro:leg side="r" num="2" coxa_y_val = "-0.03" femur_z_val = "0.067" tibia_box_z_val = "0.008" x="0" 		y="-0.20955" 	ang="-${pi/2}" />
	<xacro:leg side="r" num="3" coxa_y_val = "-0.03" femur_z_val = "0.067" tibia_box_z_val = "0.008" x="-0.262794" 	y="-0.151725" 	ang="-${pi*2/3}" />
	<xacro:leg side="l" num="1" coxa_y_val = "0.03" femur_z_val = "-0.067" tibia_box_z_val = "-0.008" x="0.262794" 	y="0.151725"	ang="${pi/3}" />
	<xacro:leg side="l" num="2" coxa_y_val = "0.03" femur_z_val = "-0.067" tibia_box_z_val = "-0.008" x="0" 		y="0.20955"	ang="${pi/2}" />
	<xacro:leg side="l" num="3" coxa_y_val = "0.03" femur_z_val = "-0.067" tibia_box_z_val = "-0.008" x="-0.262794" 	y="0.151725" 	ang="${pi*2/3}" />
</robot>
